PROBLEMS

There was a problem with 10200sim0t1, sim1t1, sim8t1, sim12t1, sim13t1

distributed.worker - WARNING -  Compute Failed
Function:  execute_task
args:      ((<function apply at 0x1a1cfed170>, <function sim_timepath at 0x1a2128ff80>, [0.8061902360588228, 0.24999999999999997, 1.333725990528466, 16.123804721176455, 0.6153773158901109, 0.0, 25, 2.7627988242892965, -inf, 0.27738957312183377, 2.7627988242892965, array([1., 0.]), 1.0, 0.3333333333333333, 0.0, None, 1e-05, 1e-05, 0.0, 25], (<class 'dict'>, [['H_ind', 1], ['risk_type_ind', 0], ['risk_val_ind', 2], ['avgrtp1_ind', 0], ['avgrbart_ind', 0], ['S_ind', 0], ['zt_vec', array([ 0.        ,  0.69351678,  0.32020165, -0.2719715 , -0.62501389,
       -0.31165743, -0.81764736,  0.06958278, -0.07733045,  0.06557351,
       -0.19079039, -0.20506202, -0.80180544, -0.30436012,  0.04839885,
       -0.59354102, -0.13266852, -0.31423981,  0.23409795, -0.14516442,
        0.56259717,  0.12726917,  0.06076556, -0.16620979,  1.684547  ])], ['rand_seed', 25]])))
kwargs:    {}
Exception: UnboundLocalError("local variable 'A_min_cdf' referenced before assignment")

Traceback (most recent call last):
  File "B19_sims.py", line 373, in <module>
    simulations = delayed(simulations).compute()
  File "/Users/rwe/opt/anaconda3/lib/python3.7/site-packages/dask/base.py", line 165, in compute
    (result,) = compute(self, traverse=False, **kwargs)
  File "/Users/rwe/opt/anaconda3/lib/python3.7/site-packages/dask/base.py", line 436, in compute
    results = schedule(dsk, keys, **kwargs)
  File "/Users/rwe/opt/anaconda3/lib/python3.7/site-packages/distributed/client.py", line 2545, in get
    results = self.gather(packed, asynchronous=asynchronous, direct=direct)
  File "/Users/rwe/opt/anaconda3/lib/python3.7/site-packages/distributed/client.py", line 1845, in gather
    asynchronous=asynchronous,
  File "/Users/rwe/opt/anaconda3/lib/python3.7/site-packages/distributed/client.py", line 762, in sync
    self.loop, func, *args, callback_timeout=callback_timeout, **kwargs
  File "/Users/rwe/opt/anaconda3/lib/python3.7/site-packages/distributed/utils.py", line 333, in sync
    raise exc.with_traceback(tb)
  File "/Users/rwe/opt/anaconda3/lib/python3.7/site-packages/distributed/utils.py", line 317, in f
    result[0] = yield future
  File "/Users/rwe/opt/anaconda3/lib/python3.7/site-packages/tornado/gen.py", line 735, in run
    value = future.result()
  File "/Users/rwe/opt/anaconda3/lib/python3.7/site-packages/distributed/client.py", line 1701, in _gather
    raise exception.with_traceback(traceback)
  File "/Users/rwe/opt/anaconda3/lib/python3.7/site-packages/dask/utils.py", line 29, in apply
    return func(*args, **kwargs)
  File "/Users/rwe/Documents/Economics/OSE/PubDebtNegShocks/code/Blanchard2019/B19_funcs.py", line 705, in sim_timepath
    eul_err) = get_k2tp1(k2t, zt, k2tp1_args)
  File "/Users/rwe/Documents/Economics/OSE/PubDebtNegShocks/code/Blanchard2019/B19_funcs.py", line 631, in get_k2tp1
    Ex_args = (k2tp1, zt, A_min, A_min_cdf, rho, mu, nvec, epsilon,
UnboundLocalError: local variable 'A_min_cdf' referenced before assignment


